Workbook

Sheet Sheet1
A1: Name | B1: Recombination-resistant strong terminators | C1: Recombination-resistant medium terminators | D1: Scaffold 1 | E1: Sequence | F1: Average Uninduced GFP | G1: Average Induced GFP | H1: Average Uninduced RFP | I1: Average Induced RFP | J1: Average GFP/RFP | K1: Average Strength | L1: Standard Deviation of Uninduced GFP | M1: Standard Deviation of Induced GFP | N1: Standard Deviation of Uninduced RFP | O1: Standard Deviation of Induced RFP | P1: Standard Deviation of GFP/RFP | Q1: Standard Deviation of Strength | R1: A-tract | S1: Hairpin | T1: Structure | U1: Loop | V1: U-tract | W1: ∆GU | X1: ∆GL | Y1: ∆GH | Z1: ∆GA | AA1: ∆GB | AB1: Predicted TS
A2: L3S2P21 | B2: X | C2: X | E2: CTCGGTACCAAATTCCAGAAAAGAGGCCTCCCGAAAGGGGGGCCTTTTTTCGTTTTGGTCC | F2: 70.533333 | G2: 21100 | H2: 16.693333 | I2: 27.95 | J2: 760.43846 | K2: 382.12988 | L2: 9.5143751 | M2: 5374.0115 | N2: 16.261692 | O2: 8.4145707 | P2: 36.663743 | Q2: 18.423991 | R2: AGAAAAGA | S2: GGCCUCCCGAAAGGGGGGCC | T2: ((((((((....)))))))) | U2: GAAA | V2: UUUUUUCGUUUU | W2: -1.132615 | X2: 0.4 | Y2: -19.8 | Z2: -9.1 | AA2: -10 | AB2: =1+1/(0.005*EXP(0.6*X2)+6*EXP(0.45*(Z2+AA2-W2))*(1+0.005*EXP(0.6*X2))) -> 122.71143
A3: L3S2P56 | E3: CTCGGTACCAAATTTTCGAAAAAAGACGCTGAAAAGCGTCTTTTTTCGTTTTGGTCC | F3: 67 | G3: 15900 | H3: 8.33 | I3: 22.6 | J3: 703.53982 | K3: 353.5376 | L3: 7.9903066 | M3: 1484.9242 | N3: 0.25455844 | O3: 2.3334524 | P3: 6.0522175 | Q3: 3.0413153 | R3: CGAAAAAA | S3: GACGCUGAAAAGCGUC | T3: ((((((....)))))) | U3: GAAA | V3: UUUUUUCGUUUU | W3: -1.132615 | X3: 2.7 | Y3: -9.8 | Z3: -11.4 | AA3: -7 | AB3: =1+1/(0.005*EXP(0.6*X3)+6*EXP(0.45*(Z3+AA3-W3))*(1+0.005*EXP(0.6*X3))) -> 36.891312
A4: L3S2P51 | E4: CTCGGTACCAAAAAAAAAAAAAAAGACGCTGAAAAGCGTCTTTTTTCGTTTTGGTCC | F4: 76.933333 | G4: 24833.333 | H4: 7.6566667 | I4: 40.366667 | J4: 615.94141 | K4: 309.5183 | L4: 7.9324229 | M4: 3350.1244 | N4: 0.83978172 | O4: 5.8346665 | P4: 23.067261 | Q4: 11.591588 | R4: AAAAAAAA | S4: GACGCUGAAAAGCGUC | T4: ((((((....)))))) | U4: GAAA | V4: UUUUUUCGUUUU | W4: -1.132615 | X4: 2.7 | Y4: -9.8 | Z4: -6.1 | AA4: -7 | AB4: =1+1/(0.005*EXP(0.6*X4)+6*EXP(0.45*(Z4+AA4-W4))*(1+0.005*EXP(0.6*X4))) -> 19.705432
A5: L3S1P56 | D5: X | E5: TTTTCGAAAAAAGGCCTCCCAAATCGGGGGGCCTTTTTTATTGATAACAAAA | F5: 74.166667 | G5: 21433.333 | H5: 8.7733333 | I5: 35.266667 | J5: 608.93471 | K5: 305.99734 | L5: 19.161507 | M5: 6436.0961 | N5: 1.4331899 | O5: 10.960079 | P5: 16.9618 | Q5: 8.5235176 | R5: CGAAAAAA | S5: GGCCUCCCAAAUCGGGGGGCC | T5: ((((((((.....)))))))) | U5: AAAUC | V5: UUUUUUAUUGAU | W5: 0.56495 | X5: 4.1 | Y5: -16.1 | Z5: -6.1 | AA5: -10 | AB5: =1+1/(0.005*EXP(0.6*X5)+6*EXP(0.45*(Z5+AA5-W5))*(1+0.005*EXP(0.6*X5))) -> 17.118765
A6: L3S3P41 | C6: X | E6: AAAAAAAAAAAACACCCTAACGGGTGTTTTTTTTTTTTTGGTCTCCC | F6: 78.133333 | G6: 21066.667 | H6: 7.91 | I6: 37.633333 | J6: 560.98451 | K6: 281.90176 | L6: 7.0599811 | M6: 2010.8042 | N6: 1.1186152 | O6: 3.9878984 | P6: 33.492115 | Q6: 16.830208 | R6: AAAAAAAA | S6: CACCCUAACGGGUG | T6: (((((....))))) | U6: UAAC | V6: UUUUUUUUUUUU | W6: 1.635805 | X6: 2.2 | Y6: -8.7 | Z6: -8 | AA6: -7.6 | AB6: =1+1/(0.005*EXP(0.6*X6)+6*EXP(0.45*(Z6+AA6-W6))*(1+0.005*EXP(0.6*X6))) -> 47.873772
A7: L3S3P51 | E7: AAAAAAAAAAAACACCCTAACGGGTGTTTTTTTGTTTCTGGTCTCCC | F7: 71.2 | G7: 21000 | H7: 8.58 | I7: 37.5 | J7: 560 | K7: 281.40704 | L7: 9.1923882 | M7: 3252.6912 | N7: 0.57275649 | O7: 16.122035 | P7: 95.781894 | Q7: 48.131605 | R7: AAAAAAAA | S7: CACCCUAACGGGUG | T7: (((((....))))) | U7: UAAC | V7: UUUUUUUGUUUC | W7: 0.254605 | X7: 2.2 | Y7: -8.7 | Z7: -7.1 | AA7: -7.6 | AB7: =1+1/(0.005*EXP(0.6*X7)+6*EXP(0.45*(Z7+AA7-W7))*(1+0.005*EXP(0.6*X7))) -> 39.429645
A8: L3S1P52 | D8: X | E8: TCTAACTAAAAAGGCCTCCCAAATCGGGGGGCCTTTTTTATTGATAACAAAA | F8: 58.65 | G8: 17468.75 | H8: 6.6175 | I8: 30.975 | J8: 554.29636 | K8: 278.54088 | L8: 26.181227 | M8: 6803.5951 | N8: 1.0586902 | O8: 10.166407 | P8: 56.092211 | Q8: 28.187041 | R8: ACUAAAAA | S8: GGCCUCCCAAAUCGGGGGGCC | T8: ((((((((.....)))))))) | U8: AAAUC | V8: UUUUUUAUUGAU | W8: 0.56495 | X8: 4.1 | Y8: -16.1 | Z8: -5.2 | AA8: -10 | AB8: =1+1/(0.005*EXP(0.6*X8)+6*EXP(0.45*(Z8+AA8-W8))*(1+0.005*EXP(0.6*X8))) -> 16.67527
A9: L3S2P41 | C9: X | E9: CTCGGTACCAAAAAAAAAAAAAAAGACGCTGAAAAGCGTCTTTTTTTTTTTTGGTCC | F9: 56.866667 | G9: 15574 | H9: 7.4266667 | I9: 29.6 | J9: 549.10639 | K9: 275.93286 | L9: 3.3857545 | M9: 5149.6435 | N9: 1.0128343 | O9: 13.856767 | P9: 88.319007 | Q9: 44.38141 | R9: AAAAAAAA | S9: GACGCUGAAAAGCGUC | T9: ((((((....)))))) | U9: GAAA | V9: UUUUUUUUUUUU | W9: 1.635805 | X9: 2.7 | Y9: -9.8 | Z9: -7.9 | AA9: -7 | AB9: =1+1/(0.005*EXP(0.6*X9)+6*EXP(0.45*(Z9+AA9-W9))*(1+0.005*EXP(0.6*X9))) -> 35.633024
A10: L3S2P22 | E10: CTCGGTACCAAATTCCAGAAAAGAGGCCGCGAAAGCGGCCTTTTTTCGTTTTGGTCC | F10: 70.2 | G10: 17200 | H10: 7.85 | I10: 31.9 | J10: 539.18495 | K10: 270.94721 | L10: 4.4547727 | M10: 6989.0434 | N10: 0.10606602 | O10: 14.919953 | P10: 283.65392 | Q10: 142.53966 | R10: AGAAAAGA | S10: GGCCGCGAAAGCGGCC | T10: ((((((....)))))) | U10: GAAA | V10: UUUUUUCGUUUU | W10: -1.132615 | X10: 0.4 | Y10: -15.4 | Z10: -9.1 | AA10: -10 | AB10: =1+1/(0.005*EXP(0.6*X10)+6*EXP(0.45*(Z10+AA10-W10))*(1+0.005*EXP(0.6*X10))) -> 122.71143
A11: L3S2P11 | B11: X | C11: X | E11: CTCGGTACCAAATTCCAGAAAAGAGACGCTTTCGAGCGTCTTTTTTCGTTTTGGTCC | F11: 58.775 | G11: 16595.5 | H11: 7.62 | I11: 31.45 | J11: 520.48133 | K11: 261.54841 | L11: 20.379953 | M11: 5727.8572 | N11: 1.8494864 | O11: 8.5582319 | P11: 75.560073 | Q11: 37.969886 | R11: AGAAAAGA | S11: GACGCUUUCGAGCGUC | T11: ((((((....)))))) | U11: UUCG | V11: UUUUUUCGUUUU | W11: -1.132615 | X11: 5.1 | Y11: -7.4 | Z11: -9.1 | AA11: -7 | AB11: =1+1/(0.005*EXP(0.6*X11)+6*EXP(0.45*(Z11+AA11-W11))*(1+0.005*EXP(0.6*X11))) -> 9.7315526
A12: L3S2P55 | B12: X | E12: CTCGGTACCAAAGACGAACAATAAGACGCTGAAAAGCGTCTTTTTTCGTTTTGGTCC | F12: 62.225 | G12: 27975 | H12: 7.24 | I12: 55.65 | J12: 508.76679 | K12: 255.6617 | L12: 18.648928 | M12: 5395.9089 | N12: 0.64161255 | O12: 10.303559 | P12: 104.1225 | Q12: 52.322863 | R12: AACAAUAA | S12: GACGCUGAAAAGCGUC | T12: ((((((....)))))) | U12: GAAA | V12: UUUUUUCGUUUU | W12: -1.132615 | X12: 2.7 | Y12: -9.8 | Z12: -2.5 | AA12: -7 | AB12: =1+1/(0.005*EXP(0.6*X12)+6*EXP(0.45*(Z12+AA12-W12))*(1+0.005*EXP(0.6*X12))) -> 6.9617102
A13: L3S3P21 | B13: X | C13: X | E13: CCAATTATTGAAGGCCTCCCTAACGGGGGGCCTTTTTTTGTTTCTGGTCTCCC | F13: 85.4 | G13: 23266.667 | H13: 7.7266667 | I13: 47.866667 | J13: 490.71954 | K13: 246.59273 | L13: 11.407015 | M13: 2157.1586 | N13: 0.72590174 | O13: 8.0307741 | P13: 41.802205 | Q13: 21.006133 | R13: UUAUUGAA | S13: GGCCUCCCUAACGGGGGGCC | T13: ((((((((....)))))))) | U13: UAAC | V13: UUUUUUUGUUUC | W13: 0.254605 | X13: 2.2 | Y13: -18 | Z13: -3.8 | AA13: -10 | AB13: =1+1/(0.005*EXP(0.6*X13)+6*EXP(0.45*(Z13+AA13-W13))*(1+0.005*EXP(0.6*X13))) -> 34.705534
A14: L3S3P56 | E14: TTTTCGAAAAAACACCCTAACGGGTGTTTTTTTGTTTCTGGTCTCCC | F14: 75.4 | G14: 15300 | H14: 10.2 | I14: 31.4 | J14: 487.26115 | K14: 244.85485 | L14: 2.8284271 | M14: 848.52814 | N14: 1.2020815 | O14: 5.8689863 | P14: 93.40698 | Q14: 46.938181 | R14: CGAAAAAA | S14: CACCCUAACGGGUG | T14: (((((....))))) | U14: UAAC | V14: UUUUUUUGUUUC | W14: 0.254605 | X14: 2.2 | Y14: -8.7 | Z14: -9.4 | AA14: -7.6 | AB14: =1+1/(0.005*EXP(0.6*X14)+6*EXP(0.45*(Z14+AA14-W14))*(1+0.005*EXP(0.6*X14))) -> 47.922257
A15: L3S2P52 | E15: CTCGGTACCAAATCTAACTAAAAAGACGCTGAAAAGCGTCTTTTTTCGTTTTGGTCC | F15: 63.95 | G15: 17950 | H15: 7.695 | I15: 36.15 | J15: 487.12981 | K15: 244.78885 | L15: 41.931432 | M15: 10677.312 | N15: 2.397092 | O15: 2.6162951 | P15: 260.10614 | Q15: 130.7066 | R15: ACUAAAAA | S15: GACGCUGAAAAGCGUC | T15: ((((((....)))))) | U15: GAAA | V15: UUUUUUCGUUUU | W15: -1.132615 | X15: 2.7 | Y15: -9.8 | Z15: -5.2 | AA15: -7 | AB15: =1+1/(0.005*EXP(0.6*X15)+6*EXP(0.45*(Z15+AA15-W15))*(1+0.005*EXP(0.6*X15))) -> 15.806432
A16: L3S1P51 | D16: X | E16: AAAAAAAAAAAAGGCCTCCCAAATCGGGGGGCCTTTTTTATTGATAACAAAA | F16: 77.333333 | G16: 18666.667 | H16: 7.6433333 | I16: 39.6 | J16: 471.07826 | K16: 236.72274 | L16: 10.864775 | M16: 8857.3886 | N16: 1.5614203 | O16: 8.3624159 | P16: 191.36342 | Q16: 96.162524 | R16: AAAAAAAA | S16: GGCCUCCCAAAUCGGGGGGCC | T16: ((((((((.....)))))))) | U16: AAAUC | V16: UUUUUUAUUGAU | W16: 0.56495 | X16: 4.1 | Y16: -16.1 | Z16: -6.1 | AA16: -10 | AB16: =1+1/(0.005*EXP(0.6*X16)+6*EXP(0.45*(Z16+AA16-W16))*(1+0.005*EXP(0.6*X16))) -> 17.118765
A17: L3S2P13 | E17: CTCGGTACCAAATTCCAGAAAAGAGACGCTTAACAGCGTCTTTTTTCGTTTTGGTCC | F17: 59.3 | G17: 12600 | H17: 8.12 | I17: 26.8 | J17: 470.14925 | K17: 236.25591 | L17: 8.131728 | M17: 636.3961 | N17: 1.1808683 | O17: 9.4752309 | P17: 94.984493 | Q17: 47.730901 | R17: AGAAAAGA | S17: GACGCUUAACAGCGUC | T17: ((((((....)))))) | U17: UAAC | V17: UUUUUUCGUUUU | W17: -1.132615 | X17: 5.5 | Y17: -7 | Z17: -9.1 | AA17: -7 | AB17: =1+1/(0.005*EXP(0.6*X17)+6*EXP(0.45*(Z17+AA17-W17))*(1+0.005*EXP(0.6*X17))) -> 7.9609384
A18: L3S3P22 | B18: X | C18: X | E18: CCAATTATTGAAGGCCGCTAACGCGGCCTTTTTTTGTTTCTGGTCTCCC | F18: 68.733333 | G18: 12966.667 | H18: 7.62 | I18: 28.5 | J18: 460.9382 | K18: 231.62724 | L18: 20.412333 | M18: 1106.044 | N18: 0.81461647 | O18: 4.9112117 | P18: 55.842554 | Q18: 28.061585 | R18: UUAUUGAA | S18: GGCCGCUAACGCGGCC | T18: ((((((....)))))) | U18: UAAC | V18: UUUUUUUGUUUC | W18: 0.254605 | X18: 2.2 | Y18: -13.6 | Z18: -3.8 | AA18: -10 | AB18: =1+1/(0.005*EXP(0.6*X18)+6*EXP(0.45*(Z18+AA18-W18))*(1+0.005*EXP(0.6*X18))) -> 34.705534
A19: L3S1P53 | D19: X | E19: CCAATTATTGAAGGCCTCCCAAATCGGGGGGCCTTTTTTATTGATAACAAAA | F19: 88.533333 | G19: 23700 | H19: 8.65 | I19: 53.233333 | J19: 450.72835 | K19: 226.49666 | L19: 8.597868 | M19: 4731.8073 | N19: 1.6290795 | O19: 13.587617 | P19: 35.129998 | Q19: 17.653266 | R19: UUAUUGAA | S19: GGCCUCCCAAAUCGGGGGGCC | T19: ((((((((.....)))))))) | U19: AAAUC | V19: UUUUUUAUUGAU | W19: 0.56495 | X19: 4.1 | Y19: -16.1 | Z19: -4.3 | AA19: -10 | AB19: =1+1/(0.005*EXP(0.6*X19)+6*EXP(0.45*(Z19+AA19-W19))*(1+0.005*EXP(0.6*X19))) -> 16.054249
A20: L3S3P00 | B20: X | C20: X | E20: CCAATTATTGAAGGGGAGCGGGAAACCGCTCCCCTTTTTTTGTTTCTGGTCTCCC | F20: 64.5 | G20: 18750 | H20: 7.1975 | I20: 42.225 | J20: 440.89193 | K20: 221.55373 | L20: 22.432566 | M20: 4215.4478 | N20: 1.1620492 | O20: 6.1748819 | P20: 58.098776 | Q20: 29.195365 | R20: UUAUUGAA | S20: GGGGAGCGGGAAACCGCUCCCC | T20: (((((((((....))))))))) | U20: GAAA | V20: UUUUUUUGUUUC | W20: 0.254605 | X20: 0.2 | Y20: -23.3 | Z20: -3.8 | AA20: -9.9 | AB20: =1+1/(0.005*EXP(0.6*X20)+6*EXP(0.45*(Z20+AA20-W20))*(1+0.005*EXP(0.6*X20))) -> 60.010657
A21: L3S2P53 | E21: CTCGGTACCAAACCAATTATTGAAGACGCTGAAAAGCGTCTTTTTTCGTTTTGGTCC | F21: 82 | G21: 21900 | H21: 8.1533333 | I21: 50.866667 | J21: 433.52756 | K21: 217.85304 | L21: 8.0517079 | M21: 3686.4617 | N21: 0.28005952 | O21: 11.065412 | P21: 21.897415 | Q21: 11.003726 | R21: UUAUUGAA | S21: GACGCUGAAAAGCGUC | T21: ((((((....)))))) | U21: GAAA | V21: UUUUUUCGUUUU | W21: -1.132615 | X21: 2.7 | Y21: -9.8 | Z21: -3.8 | AA21: -7 | AB21: =1+1/(0.005*EXP(0.6*X21)+6*EXP(0.45*(Z21+AA21-W21))*(1+0.005*EXP(0.6*X21))) -> 10.556827
A22: L3S2P15 | E22: CTCGGTACCAAATTCCAGAAAAGAGACGCTTTTAGAGCGTCTTTTTTCGTTTTGGTCC | F22: 56.75 | G22: 15893.25 | H22: 7.075 | I22: 36.325 | J22: 431.0425 | K22: 216.60427 | L22: 15.084319 | M22: 4346.6748 | N22: 1.3829799 | O22: 6.1554177 | P22: 60.428616 | Q22: 30.366139 | R22: AAAAGAGA | S22: CGCUUUUAGAGCG | T22: (((((...))))) | U22: UUA | V22: UCUUUUUUCGUU | W22: -0.330725 | X22: 6.2 | Y22: -3 | Z22: -10.8 | AA22: -7.9 | AB22: =1+1/(0.005*EXP(0.6*X22)+6*EXP(0.45*(Z22+AA22-W22))*(1+0.005*EXP(0.6*X22))) -> 5.8034753
A23: L3S2P31 | E23: CTCGGTACCAAATTCCAGAAAAGAGACGCTGAAAAGCGTCTTTTTTTTTTTTGGTCC | F23: 61.825 | G23: 15011.5 | H23: 7.1725 | I23: 40.1 | J23: 372.91871 | K23: 187.39634 | L23: 23.009473 | M23: 5380.9908 | N23: 1.5868496 | O23: 14.035194 | P23: 53.108488 | Q23: 26.687682 | R23: AGAAAAGA | S23: GACGCUGAAAAGCGUC | T23: ((((((....)))))) | U23: GAAA | V23: UUUUUUUUUUUU | W23: 1.635805 | X23: 2.7 | Y23: -9.8 | Z23: -8.1 | AA23: -7 | AB23: =1+1/(0.005*EXP(0.6*X23)+6*EXP(0.45*(Z23+AA23-W23))*(1+0.005*EXP(0.6*X23))) -> 36.009622
A24: L3S1P13 | B24: X | C24: X | D24: X | E24: GACGAACAATAAGGCCTCCCTAACGGGGGGCCTTTTTTATTGATAACAAAA | F24: 49.033333 | G24: 13019 | H24: 14.566667 | I24: 35.6 | J24: 354.09794 | K24: 177.93867 | L24: 23.76475 | M24: 6150.2913 | N24: 0.89628864 | O24: 5.9025418 | P24: 109.76405 | Q24: 55.157812 | R24: AACAAUAA | S24: GGCCUCCCUAACGGGGGGCC | T24: ((((((((....)))))))) | U24: UAAC | V24: UUUUUUAUUGAU | W24: 0.56495 | X24: 2.2 | Y24: -18 | Z24: -2.5 | AA24: -10 | AB24: =1+1/(0.005*EXP(0.6*X24)+6*EXP(0.45*(Z24+AA24-W24))*(1+0.005*EXP(0.6*X24))) -> 28.922914
A25: L3S3P11 | B25: X | C25: X | E25: CCAATTATTGAACACCCTTCGGGGTGTTTTTTTGTTTCTGGTCTCCC | F25: 60.75 | G25: 15290 | H25: 7.755 | I25: 43.1 | J25: 343.47133 | K25: 172.59866 | L25: 33.728993 | M25: 8358.0022 | N25: 2.3688077 | O25: 7.0710678 | P25: 137.5706 | Q25: 69.130957 | R25: UUAUUGAA | S25: CACCCUUCGGGGUG | T25: (((((....))))) | U25: UUCG | V25: UUUUUUUGUUUC | W25: 0.254605 | X25: 0.8 | Y25: -10.1 | Z25: -3.9 | AA25: -7.6 | AB25: =1+1/(0.005*EXP(0.6*X25)+6*EXP(0.45*(Z25+AA25-W25))*(1+0.005*EXP(0.6*X25))) -> 26.914513
A26: L3S3P23 | B26: X | C26: X | E26: CCAATTATTGAAGACGCTTAACAGCGTCTTTTTTTGTTTCTGGTCTCCC | F26: 65.475 | G26: 15534.5 | H26: 8.125 | I26: 45.8 | J26: 334.67936 | K26: 168.18058 | L26: 16.383401 | M26: 7575.0266 | N26: 1.9708289 | O26: 5.0892043 | P26: 146.85642 | Q26: 73.797198 | R26: UUAUUGAA | S26: GACGCUUAACAGCGUC | T26: ((((((....)))))) | U26: UAAC | V26: UUUUUUUGUUUC | W26: 0.254605 | X26: 5.5 | Y26: -7 | Z26: -3.8 | AA26: -7 | AB26: =1+1/(0.005*EXP(0.6*X26)+6*EXP(0.45*(Z26+AA26-W26))*(1+0.005*EXP(0.6*X26))) -> 6.4748414
A27: L3S1P12 | D27: X | E27: GACGAACAATAAGGCCTCCCGAAAGGGGGGCCTTTTTTATTGATAACAAAA | F27: 74.366667 | G27: 17533.333 | H27: 16.166667 | I27: 54.033333 | J27: 331.33093 | K27: 166.49796 | L27: 12.461675 | M27: 5173.329 | N27: 3.592121 | O27: 20.772658 | P27: 26.782008 | Q27: 13.458295 | R27: AACAAUAA | S27: GGCCUCCCGAAAGGGGGGCC | T27: ((((((((....)))))))) | U27: GAAA | V27: UUUUUUAUUGAU | W27: 0.56495 | X27: 0.4 | Y27: -19.8 | Z27: -2.5 | AA27: -10 | AB27: =1+1/(0.005*EXP(0.6*X27)+6*EXP(0.45*(Z27+AA27-W27))*(1+0.005*EXP(0.6*X27))) -> 44.020773
A28: L3S3P52 | E28: TCTAACTAAAAACACCCTAACGGGTGTTTTTTTGTTTCTGGTCTCCC | F28: 75 | G28: 18300 | H28: 9.38 | I28: 56.2 | J28: 325.62278 | K28: 163.62954 | L28: 9.9702056 | M28: 3606.2446 | N28: 0.79195959 | O28: 3.6769553 | P28: 78.233631 | Q28: 39.313383 | R28: ACUAAAAA | S28: CACCCUAACGGGUG | T28: (((((....))))) | U28: UAAC | V28: UUUUUUUGUUUC | W28: 0.254605 | X28: 2.2 | Y28: -8.7 | Z28: -5.3 | AA28: -7.6 | AB28: =1+1/(0.005*EXP(0.6*X28)+6*EXP(0.45*(Z28+AA28-W28))*(1+0.005*EXP(0.6*X28))) -> 29.460121
A29: L3S3P12 | E29: CCAATTATTGAACACCCGAAAGGGTGTTTTTTTGTTTCTGGTCTCCC | F29: 66.633333 | G29: 17566.667 | H29: 8.6566667 | I29: 56.066667 | J29: 313.48164 | K29: 157.52846 | L29: 12.911365 | M29: 642.91005 | N29: 1.2608066 | O29: 2.5540817 | P29: 8.7887662 | Q29: 4.4164654 | R29: UUAUUGAA | S29: CACCCGAAAGGGUG | T29: (((((....))))) | U29: GAAA | V29: UUUUUUUGUUUC | W29: 0.254605 | X29: 0.4 | Y29: -10.5 | Z29: -3.9 | AA29: -7.6 | AB29: =1+1/(0.005*EXP(0.6*X29)+6*EXP(0.45*(Z29+AA29-W29))*(1+0.005*EXP(0.6*X29))) -> 28.164972
A30: L3S1P41 | D30: X | E30: AAAAAAAAAAAAGGCCTCCCAAATCGGGGGGCCTTTTTTTTTTTTAACAAAA | F30: 70.666667 | G30: 20833.333 | H30: 9.2066667 | I30: 68.533333 | J30: 313.4605 | K30: 157.51784 | L30: 14.15992 | M30: 7102.347 | N30: 2.3272588 | O30: 30.974398 | P30: 32.774409 | Q30: 16.469552 | R30: AAAAAAAA | S30: GGCCUCCCAAAUCGGGGGGCC | T30: ((((((((.....)))))))) | U30: AAAUC | V30: UUUUUUUUUUUU | W30: 1.635805 | X30: 4.1 | Y30: -16.1 | Z30: -7.9 | AA30: -10 | AB30: =1+1/(0.005*EXP(0.6*X30)+6*EXP(0.45*(Z30+AA30-W30))*(1+0.005*EXP(0.6*X30))) -> 17.809567
A31: L3S2P24 | B31: X | C31: X | E31: CTCGGTACCAAATTCCAGAAAAGACACCCGAAAGGGTGTTTTTTCGTTTTGGTCC | F31: 67.625 | G31: 22225 | H31: 8.15 | I31: 73.675 | J31: 300.81661 | K31: 151.16413 | L31: 17.385315 | M31: 4296.0253 | N31: 2.4579802 | O31: 10.31031 | P31: 33.518487 | Q31: 16.843461 | R31: AGAAAAGA | S31: CACCCGAAAGGGUG | T31: (((((....))))) | U31: GAAA | V31: UUUUUUCGUUUU | W31: -1.132615 | X31: 0.4 | Y31: -10.5 | Z31: -9.2 | AA31: -7.6 | AB31: =1+1/(0.005*EXP(0.6*X31)+6*EXP(0.45*(Z31+AA31-W31))*(1+0.005*EXP(0.6*X31))) -> 87.265739
A32: L3S2P14 | E32: CTCGGTACCAAATTCCAGAAAAGAGACGCTAAATCAGCGTCTTTTTTCGTTTTGGTCC | F32: 75 | G32: 18166.667 | H32: 8.23 | I32: 61.733333 | J32: 295.98569 | K32: 148.73653 | L32: 6.4210591 | M32: 2909.1809 | N32: 0.61245408 | O32: 12.302168 | P32: 14.221669 | Q32: 7.1465674 | R32: AGAAAAGA | S32: GACGCUAAAUCAGCGUC | T32: ((((((.....)))))) | U32: AAAUC | V32: UUUUUUCGUUUU | W32: -1.132615 | X32: 5.3 | Y32: -7.2 | Z32: -9.1 | AA32: -7 | AB32: =1+1/(0.005*EXP(0.6*X32)+6*EXP(0.45*(Z32+AA32-W32))*(1+0.005*EXP(0.6*X32))) -> 8.7990905
A33: L3S1P54 | D33: X | E33: TTCCAGAAAAGAGGCCTCCCAAATCGGGGGGCCTTTTTTATTGATAACAAAA | F33: 73.425 | G33: 17050 | H33: 7.215 | I33: 56.6 | J33: 290.70581 | K33: 146.08332 | L33: 11.095457 | M33: 10689.715 | N33: 1.6929166 | O33: 11.118453 | P33: 133.80686 | Q33: 67.239628 | R33: AGAAAAGA | S33: GGCCUCCCAAAUCGGGGGGCC | T33: ((((((((.....)))))))) | U33: AAAUC | V33: UUUUUUAUUGAU | W33: 0.56495 | X33: 4.1 | Y33: -16.1 | Z33: -6.2 | AA33: -10 | AB33: =1+1/(0.005*EXP(0.6*X33)+6*EXP(0.45*(Z33+AA33-W33))*(1+0.005*EXP(0.6*X33))) -> 17.159056
A34: L3S1P22 | B34: X | C34: X | D34: X | E34: GACGAACAATAAGGCCGCAAATCGCGGCCTTTTTTATTGATAACAAAA | F34: 69.733333 | G34: 16233.333 | H34: 17.366667 | I34: 67.866667 | J34: 254.83489 | K34: 128.05773 | L34: 24.949215 | M34: 3932.3445 | N34: 3.0746273 | O34: 27.637354 | P34: 85.096199 | Q34: 42.761909 | R34: AACAAUAA | S34: GGCCGCAAAUCGCGGCC | T34: ((((((.....)))))) | U34: AAAUC | V34: UUUUUUAUUGAU | W34: 0.56495 | X34: 4.1 | Y34: -11.7 | Z34: -2.5 | AA34: -10 | AB34: =1+1/(0.005*EXP(0.6*X34)+6*EXP(0.45*(Z34+AA34-W34))*(1+0.005*EXP(0.6*X34))) -> 14.108246
A35: L3S2P00 | E35: CTCGGTACCAAATTCCAGAAAAGAGGGGAGCGGGAAACCGCTCCCCTTTTTTCGTTTTGGTCC | F35: 55.175 | G35: 16166.667 | H35: 10.0525 | I35: 64.633333 | J35: 253.67277 | K35: 127.47375 | L35: 16.53025 | M35: 1594.7832 | N35: 3.3071778 | O35: 9.3001792 | P35: 42.732156 | Q35: 21.473445 | R35: AGAAAAGA | S35: GGGGAGCGGGAAACCGCUCCCC | T35: (((((((((....))))))))) | U35: GAAA | V35: UUUUUUCGUUUU | W35: -1.132615 | X35: 0.2 | Y35: -23.3 | Z35: -9.1 | AA35: -9.9 | AB35: =1+1/(0.005*EXP(0.6*X35)+6*EXP(0.45*(Z35+AA35-W35))*(1+0.005*EXP(0.6*X35))) -> 132.89808
A36: L3S1P47 | B36: X | D36: X | E36: TTTTCGAAAAAAGGCCTCCCAAATCGGGGGGCCTTTTTTTATAGCAACAAAA | F36: 66.775 | G36: 16891.5 | H36: 11.855 | I36: 67.35 | J36: 245.61952 | K36: 123.4269 | L36: 27.268587 | M36: 5640.2857 | N36: 3.6762436 | O36: 17.135635 | P36: 30.557638 | Q36: 15.355597 | R36: CGAAAAAA | S36: GGCCUCCCAAAUCGGGGGGCC | T36: ((((((((.....)))))))) | U36: AAAUC | V36: UUUUUUUAUAGC | W36: 1.241825 | X36: 4.1 | Y36: -16.1 | Z36: -7.4 | AA36: -10 | AB36: =1+1/(0.005*EXP(0.6*X36)+6*EXP(0.45*(Z36+AA36-W36))*(1+0.005*EXP(0.6*X36))) -> 17.675483
A37: L3S3P45 | B37: X | C37: X | E37: TTCCAGAAAAGACACCCTAACGGGTGTTTTTTCGTTTTTGGTCTCCC | F37: 62.775 | G37: 17250 | H37: 9.355 | I37: 75.4 | J37: 235.06618 | K37: 118.12371 | L37: 21.172211 | M37: 2633.7552 | N37: 2.7808572 | O37: 16.577093 | P37: 44.955396 | Q37: 22.590651 | R37: AGAAAAGA | S37: CACCCUAACGGGUG | T37: (((((....))))) | U37: UAAC | V37: UUUUUUCGUUUU | W37: -1.132615 | X37: 2.2 | Y37: -8.7 | Z37: -9.2 | AA37: -7.6 | AB37: =1+1/(0.005*EXP(0.6*X37)+6*EXP(0.45*(Z37+AA37-W37))*(1+0.005*EXP(0.6*X37))) -> 42.636724
A38: L3S2P44 | B38: X | C38: X | E38: CTCGGTACCAAACCAATTATTGAAGACGCTGAAAAGCGTCTTTTTTTGTTTCGGTCC | F38: 60.2 | G38: 15525 | H38: 7.73 | I38: 67.325 | J38: 230.90212 | K38: 116.03121 | L38: 19.380574 | M38: 3866.4152 | N38: 1.1733144 | O38: 5.6310893 | P38: 57.731498 | Q38: 29.010803 | R38: UUAUUGAA | S38: GACGCUGAAAAGCGUC | T38: ((((((....)))))) | U38: GAAA | V38: UUUUUUUGUUUC | W38: 0.254605 | X38: 2.7 | Y38: -9.8 | Z38: -3.8 | AA38: -7 | AB38: =1+1/(0.005*EXP(0.6*X38)+6*EXP(0.45*(Z38+AA38-W38))*(1+0.005*EXP(0.6*X38))) -> 15.753173
A39: L3S3P54 | E39: TTCCAGAAAAGACACCCTAACGGGTGTTTTTTTGTTTCTGGTCTCCC | F39: 66.266667 | G39: 14633.333 | H39: 9.07 | I39: 67.5 | J39: 227.00698 | K39: 114.07386 | L39: 20.711671 | M39: 4309.679 | N39: 2.0350184 | O39: 31.036269 | P39: 39.822475 | Q39: 20.011294 | R39: AGAAAAGA | S39: CACCCUAACGGGUG | T39: (((((....))))) | U39: UAAC | V39: UUUUUUUGUUUC | W39: 0.254605 | X39: 2.2 | Y39: -8.7 | Z39: -7.6 | AA39: -7.6 | AB39: =1+1/(0.005*EXP(0.6*X39)+6*EXP(0.45*(Z39+AA39-W39))*(1+0.005*EXP(0.6*X39))) -> 41.733454
A40: L3S3P31 | B40: X | E40: CCAATTATTGAACACCCTAACGGGTGTTTTTTTTTTTTTGGTCTCCC | F40: 53.925 | G40: 16725 | H40: 9.055 | I40: 73.6 | J40: 226.3919 | K40: 113.76478 | L40: 20.954455 | M40: 4352.2982 | N40: 1.4187436 | O40: 14.493677 | P40: 35.396821 | Q40: 17.787347 | R40: UUAUUGAA | S40: CACCCUAACGGGUG | T40: (((((....))))) | U40: UAAC | V40: UUUUUUUUUUUU | W40: 1.635805 | X40: 2.2 | Y40: -8.7 | Z40: -3.9 | AA40: -7.6 | AB40: =1+1/(0.005*EXP(0.6*X40)+6*EXP(0.45*(Z40+AA40-W40))*(1+0.005*EXP(0.6*X40))) -> 29.347575
...

Sheet Strength CI
A1: Terminator strength with 95% confidence intervals
A3: Replicates (n) | B3: 3
A4: Confidence level | B4: 0.95
A5: t multiplier | B5: =_xlfn.T.INV.2T(1-B4,B3-1) -> 4.3026527
A7: Rank | B7: Terminator | C7: Strength | D7: SD | E7: CI half-width | F7: Lower 95% | G7: Upper 95% | H7: Lower (plot floor) | I7: Rank | J7: Lower 95% | K7: Strength | L7: Upper 95%
A8: 1 | B8: {=INDEX(Sheet1!$A:$A,267-$A8)} -> L2U5H11 | C8: {=INDEX(Sheet1!$K:$K,267-$A8)} -> 0.32634552 | D8: {=INDEX(Sheet1!$Q:$Q,267-$A8)} -> 0.034643101 | E8: =$B$5*D8/SQRT($B$3) -> 0.086058234 | F8: =C8-E8 -> 0.24028728 | G8: =C8+E8 -> 0.41240375 | H8: =MAX(F8,C8/10) -> 0.24028728 | I8: =A8 -> 1 | J8: =H8 -> 0.24028728 | K8: =C8 -> 0.32634552 | L8: =G8 -> 0.41240375
A9: 2 | B9: {=INDEX(Sheet1!$A:$A,267-$A9)} -> L2U8H06 | C9: {=INDEX(Sheet1!$K:$K,267-$A9)} -> 0.41674123 | D9: {=INDEX(Sheet1!$Q:$Q,267-$A9)} -> 0.21795365 | E9: =$B$5*D9/SQRT($B$3) -> 0.54142688 | F9: =C9-E9 -> -0.12468566 | G9: =C9+E9 -> 0.95816811 | H9: =MAX(F9,C9/10) -> 0.041674123 | I9: =A9 -> 2 | J9: =H9 -> 0.041674123 | K9: =C9 -> 0.41674123 | L9: =G9 -> 0.95816811
A10: 3 | B10: {=INDEX(Sheet1!$A:$A,267-$A10)} -> L2U8H11 | C10: {=INDEX(Sheet1!$K:$K,267-$A10)} -> 0.50268776 | D10: {=INDEX(Sheet1!$Q:$Q,267-$A10)} -> 0.20185248 | E10: =$B$5*D10/SQRT($B$3) -> 0.50142935 | F10: =C10-E10 -> 0.0012584058 | G10: =C10+E10 -> 1.0041171 | H10: =MAX(F10,C10/10) -> 0.050268776 | I10: =A10 -> 3 | J10: =H10 -> 0.050268776 | K10: =C10 -> 0.50268776 | L10: =G10 -> 1.0041171
A11: 4 | B11: {=INDEX(Sheet1!$A:$A,267-$A11)} -> L1U6H10 | C11: {=INDEX(Sheet1!$K:$K,267-$A11)} -> 0.54809905 | D11: {=INDEX(Sheet1!$Q:$Q,267-$A11)} -> 0.12159952 | E11: =$B$5*D11/SQRT($B$3) -> 0.30206995 | F11: =C11-E11 -> 0.24602911 | G11: =C11+E11 -> 0.850169 | H11: =MAX(F11,C11/10) -> 0.24602911 | I11: =A11 -> 4 | J11: =H11 -> 0.24602911 | K11: =C11 -> 0.54809905 | L11: =G11 -> 0.850169
A12: 5 | B12: {=INDEX(Sheet1!$A:$A,267-$A12)} -> L2U8H03 | C12: {=INDEX(Sheet1!$K:$K,267-$A12)} -> 0.5502874 | D12: {=INDEX(Sheet1!$Q:$Q,267-$A12)} -> 0.098301653 | E12: =$B$5*D12/SQRT($B$3) -> 0.24419484 | F12: =C12-E12 -> 0.30609256 | G12: =C12+E12 -> 0.79448225 | H12: =MAX(F12,C12/10) -> 0.30609256 | I12: =A12 -> 5 | J12: =H12 -> 0.30609256 | K12: =C12 -> 0.5502874 | L12: =G12 -> 0.79448225
A13: 6 | B13: {=INDEX(Sheet1!$A:$A,267-$A13)} -> L2U5H01 | C13: {=INDEX(Sheet1!$K:$K,267-$A13)} -> 0.55499239 | D13: {=INDEX(Sheet1!$Q:$Q,267-$A13)} -> 0.053772501 | E13: =$B$5*D13/SQRT($B$3) -> 0.1335783 | F13: =C13-E13 -> 0.42141409 | G13: =C13+E13 -> 0.68857068 | H13: =MAX(F13,C13/10) -> 0.42141409 | I13: =A13 -> 6 | J13: =H13 -> 0.42141409 | K13: =C13 -> 0.55499239 | L13: =G13 -> 0.68857068
A14: 7 | B14: {=INDEX(Sheet1!$A:$A,267-$A14)} -> L2U8H04 | C14: {=INDEX(Sheet1!$K:$K,267-$A14)} -> 0.55899383 | D14: {=INDEX(Sheet1!$Q:$Q,267-$A14)} -> 0.10836041 | E14: =$B$5*D14/SQRT($B$3) -> 0.26918217 | F14: =C14-E14 -> 0.28981166 | G14: =C14+E14 -> 0.828176 | H14: =MAX(F14,C14/10) -> 0.28981166 | I14: =A14 -> 7 | J14: =H14 -> 0.28981166 | K14: =C14 -> 0.55899383 | L14: =G14 -> 0.828176
A15: 8 | B15: {=INDEX(Sheet1!$A:$A,267-$A15)} -> L2U5H03 | C15: {=INDEX(Sheet1!$K:$K,267-$A15)} -> 0.58171528 | D15: {=INDEX(Sheet1!$Q:$Q,267-$A15)} -> 0.019103983 | E15: =$B$5*D15/SQRT($B$3) -> 0.047456924 | F15: =C15-E15 -> 0.53425836 | G15: =C15+E15 -> 0.62917221 | H15: =MAX(F15,C15/10) -> 0.53425836 | I15: =A15 -> 8 | J15: =H15 -> 0.53425836 | K15: =C15 -> 0.58171528 | L15: =G15 -> 0.62917221
A16: 9 | B16: {=INDEX(Sheet1!$A:$A,267-$A16)} -> L1U6H03 | C16: {=INDEX(Sheet1!$K:$K,267-$A16)} -> 0.58229818 | D16: {=INDEX(Sheet1!$Q:$Q,267-$A16)} -> 0.13087092 | E16: =$B$5*D16/SQRT($B$3) -> 0.32510139 | F16: =C16-E16 -> 0.25719679 | G16: =C16+E16 -> 0.90739957 | H16: =MAX(F16,C16/10) -> 0.25719679 | I16: =A16 -> 9 | J16: =H16 -> 0.25719679 | K16: =C16 -> 0.58229818 | L16: =G16 -> 0.90739957
A17: 10 | B17: {=INDEX(Sheet1!$A:$A,267-$A17)} -> L1U6H05 | C17: {=INDEX(Sheet1!$K:$K,267-$A17)} -> 0.58485939 | D17: {=INDEX(Sheet1!$Q:$Q,267-$A17)} -> 0.12635936 | E17: =$B$5*D17/SQRT($B$3) -> 0.31389405 | F17: =C17-E17 -> 0.27096534 | G17: =C17+E17 -> 0.89875344 | H17: =MAX(F17,C17/10) -> 0.27096534 | I17: =A17 -> 10 | J17: =H17 -> 0.27096534 | K17: =C17 -> 0.58485939 | L17: =G17 -> 0.89875344
A18: 11 | B18: {=INDEX(Sheet1!$A:$A,267-$A18)} -> L1U6H09 | C18: {=INDEX(Sheet1!$K:$K,267-$A18)} -> 0.59296851 | D18: {=INDEX(Sheet1!$Q:$Q,267-$A18)} -> 0.059883582 | E18: =$B$5*D18/SQRT($B$3) -> 0.14875906 | F18: =C18-E18 -> 0.44420945 | G18: =C18+E18 -> 0.74172758 | H18: =MAX(F18,C18/10) -> 0.44420945 | I18: =A18 -> 11 | J18: =H18 -> 0.44420945 | K18: =C18 -> 0.59296851 | L18: =G18 -> 0.74172758
A19: 12 | B19: {=INDEX(Sheet1!$A:$A,267-$A19)} -> L2U8H01 | C19: {=INDEX(Sheet1!$K:$K,267-$A19)} -> 0.60562379 | D19: {=INDEX(Sheet1!$Q:$Q,267-$A19)} -> 0.17130186 | E19: =$B$5*D19/SQRT($B$3) -> 0.42553742 | F19: =C19-E19 -> 0.18008638 | G19: =C19+E19 -> 1.0311612 | H19: =MAX(F19,C19/10) -> 0.18008638 | I19: =A19 -> 12 | J19: =H19 -> 0.18008638 | K19: =C19 -> 0.60562379 | L19: =G19 -> 1.0311612
... A272: 265 | B272: {=INDEX(Sheet1!$A:$A,267-$A272)} -> L3S2P21 | C272: {=INDEX(Sheet1!$K:$K,267-$A272)} -> 382.12988 | D272: {=INDEX(Sheet1!$Q:$Q,267-$A272)} -> 18.423991 | E272: =$B$5*D272/SQRT($B$3) -> 45.767731 | F272: =C272-E272 -> 336.36215 | G272: =C272+E272 -> 427.89761 | H272: =MAX(F272,C272/10) -> 336.36215 | I272: =A272 -> 265 | J272: =H272 -> 336.36215 | K272: =C272 -> 382.12988 | L272: =G272 -> 427.89761
